# FeedMe 500 Error Fix Summary

## Problem Description
The FeedMe feature was experiencing 500 Internal Server Errors on multiple endpoints:
- `/api/v1/feedme/conversations` - List conversations
- `/api/v1/feedme/conversations/upload` - Upload transcripts

## Root Cause Analysis

### 1. **Incorrect Database Connection Import**
- **Issue**: Endpoints were importing `get_db_connection` from `app.db.embedding_utils` instead of the proper connection manager
- **Impact**: Connection pooling wasn't working correctly, causing inconsistent database access

### 2. **Missing Connection Manager Usage**
- **Issue**: Direct connection calls without proper context management
- **Impact**: Connections weren't being properly returned to the pool, leading to connection exhaustion

### 3. **Incorrect SQL Query Result Handling**
- **Issue**: `COUNT(*)` queries weren't aliased, causing dictionary key errors when using `RealDictCursor`
- **Impact**: List endpoints failed when trying to get total count

### 4. **Indentation Errors**
- **Issue**: When fixing connection handling, code blocks lost proper indentation
- **Impact**: Python syntax errors preventing module import

## Fixes Applied

### 1. **Fixed Database Connection Import**
```python
# Before
from app.db.embedding_utils import get_db_connection, get_embedding_model

# After
from app.db.connection_manager import get_connection_manager
from app.db.embedding_utils import get_embedding_model
```

### 2. **Added Connection Helper Function**
```python
def get_db_connection():
    """Get a database connection from the connection manager"""
    manager = get_connection_manager()
    return manager.get_connection(cursor_factory=psycopg2_extras.RealDictCursor)
```

### 3. **Updated All Connection Usage**
```python
# Before
conn = None
try:
    conn = get_db_connection()
    # ... code ...
finally:
    if conn:
        conn.close()

# After
try:
    with get_db_connection() as conn:
        # ... code ...
```

### 4. **Fixed SQL COUNT Queries**
```python
# Before
count_query = f"SELECT COUNT(*) FROM feedme_conversations{where_clause}"

# After
count_query = f"SELECT COUNT(*) as count FROM feedme_conversations{where_clause}"
```

### 5. **Enhanced Error Handling**
```python
except HTTPException:
    # Re-raise HTTP exceptions as-is
    raise
except psycopg2.Error as e:
    logger.error(f"Database error during upload: {e}")
    raise HTTPException(status_code=500, detail=f"Database error: {str(e)}")
except Exception as e:
    logger.error(f"Unexpected error uploading transcript: {e}", exc_info=True)
    raise HTTPException(status_code=500, detail=f"Failed to upload transcript: {str(e)}")
```

### 6. **Fixed Indentation Issues**
- Corrected indentation for all `with` statement blocks
- Ensured proper nesting of cursor operations within connection contexts

## Verification

### Test Results
All tests now pass successfully:
- ✅ Database Connection Test
- ✅ FeedMe Endpoints Import Test
- ✅ Connection Manager Singleton Test

### API Health Check Script
Created `test_feedme_api_health.py` to verify all endpoints:
```bash
python test_feedme_api_health.py
```

## Recommendations

1. **Enable Logging**: Monitor API logs for any remaining issues
2. **Test with Frontend**: Verify the UI works correctly with the fixed endpoints
3. **Monitor Performance**: Check connection pool stats to ensure proper resource usage
4. **Start Celery Worker**: For full functionality, start the FeedMe worker:
   ```bash
   ./scripts/start-feedme-worker.sh
   ```

## Files Modified
1. `/app/api/v1/endpoints/feedme_endpoints.py` - Main fixes
2. Created test scripts:
   - `test_feedme_quick_fix.py`
   - `test_feedme_api_health.py`

The FeedMe feature should now work flawlessly without 500 errors!